Workbook
Name DIRIS_Lima_Centro: Cargos!$AB:$AB
Name DIRIS_Lima_Norte: Cargos!$P:$P
Name Ejercito: Cargos!#REF!
Name Ejercito_del_Peru: Cargos!#REF!
Name Ejercito_del_Perú: Cargos!#REF!
Name Ejército_del_Perú: Cargos!$A:$A
Name EPSEL: Cargos!$AJ:$AJ
Name ESSALUD: Cargos!$T:$T
Name Fuerza_Aerea_del_Perú: Cargos!$AH:$AH
Name Gobierno_Regional_Loreto: Cargos!$AT:$AT
Name Hospital_de_apoyo_Iquitos: Cargos!$R:$R
Name Hospital_Regional_Loreto: Cargos!$AN:$AN
Name Marina: Cargos!#REF!
Name Marina_de_Guerra: Cargos!$J$1:$J$16
Name Ministerio_Defensa: Cargos!$AD:$AD
Name ONPE: Cargos!$X:$X
Name Policia: Cargos!#REF!
Name Policia_Nacional_del_Perú: Cargos!$E:$E
Name Red_Salud_APLAO: Cargos!$AP:$AP
Name RENIEC: Cargos!$N:$N
Name SENASA: Cargos!$V:$V
Name U_San_Juan_Bautista: Cargos!$Z:$Z
Name UE403_Morropon: Cargos!$AF:$AF
Name UNAP: Cargos!$AL:$AL
Name UTES_N6: Cargos!$AR:$AR

Sheet Base
A1: Convenio | B1: Periodo de Gracia | C1: Periodo Final | D1: Periodo de gracia 1 | E1: Periodo final 1 | F1: %RCI | G1: Día de corte | H1: Vencimiento | I1: Ingreso Fijo 1 | J1: Ingreso Fijo 2 | K1: Reserva | L1: RCI global | M1: PG
A2: Marina_de_Guerra | B2: 2 | C2: 3 | D2: 2 | E2: 3 | F2: 0.5 | G2: 30 | H2: 15 | I2: Remuneración Consolidada | J2: Bonificación FFAA | K2: 100 | M2: =IF(AND(Cáratula!$G$9=A2,DAY(Cáratula!$G$37)<H2),2,IF(AND(Cáratula!$G$9=A2,DAY(Cáratula!$G$37))>=H2,1,0)) -> 1
A3: Ejército_del_Perú | B3: 2 | C3: 3 | D3: 2 | E3: 3 | F3: 0.47 | G3: 30 | H3: 15 | I3: Remuneración Consolidada | J3: Bonificación FFAA | K3: =IF(AND(Cáratula!G9="Ejército_del_Perú",Cáratula!G13="Suboficial Tercera"),100,0) -> 0 | M3: =IF(AND(Cáratula!$G$9=A3,DAY(Cáratula!$G$37)<H3),2,IF(AND(Cáratula!$G$9=A3,DAY(Cáratula!$G$37))>=H3,1,0)) -> 1
A4: Policia_Nacional_del_Perú | B4: 2 | C4: 3 | D4: 2 | E4: 3 | F4: 0.45 | G4: 30 | H4: 15 | I4: Remuneración Consolidada | J4: Bonificación FFAA | M4: =IF(AND(Cáratula!$G$9=A4,DAY(Cáratula!$G$37)<H4),2,IF(AND(Cáratula!$G$9=A4,DAY(Cáratula!$G$37))>=H4,1,0)) -> 1
A5: RENIEC | B5: 1 | C5: 2 | D5: 1 | E5: 2 | F5: 0.5 | G5: 30 | H5: 10 | I5: Total Ingresos Fijos | M5: =IF(AND(Cáratula!$G$9=A5,DAY(Cáratula!$G$37)<H5),1,IF(AND(Cáratula!$G$9=A5,DAY(Cáratula!$G$37))>=H5,0,0)) -> 0
A6: DIRIS_Lima_Norte | B6: 1 | C6: 2 | D6: 1 | E6: 2 | F6: 0.5 | G6: 30 | H6: 15 | I6: Total Ingresos Fijos | K6: 50 | M6: =IF(AND(Cáratula!$G$9=A6,DAY(Cáratula!$G$37)<H6),1,IF(AND(Cáratula!$G$9=A6,DAY(Cáratula!$G$37))>=H6,0,0)) -> 0
A7: Hospital_de_apoyo_Iquitos | B7: 1 | C7: 2 | D7: 1 | E7: 2 | F7: 0.5 | G7: 30 | H7: 15 | I7: Total Ingresos Fijos | M7: =IF(AND(Cáratula!$G$9=A7,DAY(Cáratula!$G$37)<H7),1,IF(AND(Cáratula!$G$9=A7,DAY(Cáratula!$G$37))>=H7,0,0)) -> 0
A8: SENASA | B8: 1 | C8: 2 | D8: 1 | E8: 2 | F8: 0.47 | G8: 30 | H8: 17 | I8: Total Ingresos Fijos | M8: =IF(AND(Cáratula!$G$9=A8,DAY(Cáratula!$G$37)<H8),1,IF(AND(Cáratula!$G$9=A8,DAY(Cáratula!$G$37))>=H8,0,0)) -> 0
A9: ONPE | B9: 1 | C9: 2 | D9: 1 | E9: 2 | F9: 0.5 | G9: 30 | H9: 17 | I9: Total Ingresos Fijos | M9: =IF(AND(Cáratula!$G$9=A9,DAY(Cáratula!$G$37)<H9),1,IF(AND(Cáratula!$G$9=A9,DAY(Cáratula!$G$37))>=H9,0,0)) -> 0
A10: U_San_Juan_Bautista | B10: 1 | C10: 2 | D10: 1 | E10: 2 | F10: 0.3 | G10: 30 | H10: 17 | I10: Total Ingresos Fijos | M10: =IF(AND(Cáratula!$G$9=A10,DAY(Cáratula!$G$37)<H10),1,IF(AND(Cáratula!$G$9=A10,DAY(Cáratula!$G$37))>=H10,0,0)) -> 0
A11: DIRIS_Lima_Centro | B11: 1 | C11: 2 | D11: 1 | E11: 2 | F11: 0.5 | G11: 30 | H11: 15 | I11: Total Ingresos Fijos | K11: 50 | M11: =IF(AND(Cáratula!$G$9=A11,DAY(Cáratula!$G$37)<H11),1,IF(AND(Cáratula!$G$9=A11,DAY(Cáratula!$G$37))>=H11,0,0)) -> 0
A12: Ministerio_Defensa | B12: 1 | C12: 2 | D12: 1 | E12: 2 | F12: 0.5 | G12: 30 | H12: 15 | I12: Total Ingresos Fijos | L12: 0.5 | M12: =IF(AND(Cáratula!$G$9=A12,DAY(Cáratula!$G$37)<H12),1,IF(AND(Cáratula!$G$9=A12,DAY(Cáratula!$G$37))>=H12,0,0)) -> 0
A13: UE403_Morropon | B13: 1 | C13: 2 | D13: =IF(G13>H13,IF(DAY(Cáratula!$G$37)>G13,B13+1,B13+0),IF(DAY(Cáratula!$G$37)>G13,B13+1,B13)) -> 1 | E13: =IF(G13>H13,IF(DAY(Cáratula!$G$37)>G13,B13+2,B13+1),IF(DAY(Cáratula!$G$37)>G13,B13+1,B13)) -> 2 | F13: 0.5 | G13: 25 | H13: 17 | I13: Total Ingresos Fijos | M13: =IF(Cáratula!$G$9<>A13,"",IF(DAY(Cáratula!$G$37)<H13,1,IF(AND(DAY(Cáratula!$G$37)>=H13,DAY(Cáratula!$G$37)<G13),0,IF(DAY(Cáratula!$G$37)>=G13,1,""))))
A14: Fuerza_Aerea_del_Perú | B14: 2 | C14: 3 | D14: 2 | E14: 3 | F14: 0.5 | G14: 30 | H14: 17 | I14: Total Ingresos Fijos | K14: =IF(AND(Cáratula!G9="Fuerza_Aerea_del_Perú",Cáratula!G13="Personal Administrativo"),25,35) -> 35 | M14: =IF(AND(Cáratula!$G$9=A14,DAY(Cáratula!$G$37)<H14),2,IF(AND(Cáratula!$G$9=A14,DAY(Cáratula!$G$37))>=H14,1,0)) -> 1
A15: EPSEL | B15: 1 | C15: 2 | D15: =IF(G15>H15,IF(DAY(Cáratula!$G$37)>G15,B15+1,B15+0),IF(DAY(Cáratula!$G$37)>G15,B15+1,B15)) -> 1 | E15: =IF(G15>H15,IF(DAY(Cáratula!$G$37)>G15,B15+2,B15+1),IF(DAY(Cáratula!$G$37)>G15,B15+1,B15)) -> 2 | F15: 0.5 | G15: 26 | H15: 15 | I15: Total Ingresos Fijos | M15: =IF(Cáratula!$G$9<>A15,"",IF(DAY(Cáratula!$G$37)<H15,1,IF(AND(DAY(Cáratula!$G$37)>=H15,DAY(Cáratula!$G$37)<G15),0,IF(DAY(Cáratula!$G$37)>=G15,1,""))))
A16: UNAP | B16: 1 | C16: 2 | D16: 1 | E16: 2 | F16: 0.5 | G16: 30 | H16: 15 | I16: Total Ingresos Fijos | M16: =IF(AND(Cáratula!$G$9=A16,DAY(Cáratula!$G$37)<H16),1,IF(AND(Cáratula!$G$9=A16,DAY(Cáratula!$G$37))>=H16,0,0)) -> 0
A17: Hospital_Regional_Loreto | B17: 1 | C17: 2 | D17: 1 | E17: 2 | F17: 0.5 | G17: 30 | H17: 15 | I17: Total Ingresos Fijos | M17: =IF(AND(Cáratula!$G$9=A17,DAY(Cáratula!$G$37)<H17),1,IF(AND(Cáratula!$G$9=A17,DAY(Cáratula!$G$37))>=H17,0,0)) -> 0
A18: Red_Salud_APLAO | B18: 1 | C18: 2 | D18: =IF(G18>H18,IF(DAY(Cáratula!$G$37)>G18,B18+1,B18+0),IF(DAY(Cáratula!$G$37)>G18,B18+1,B18)) -> 1 | E18: =IF(G18>H18,IF(DAY(Cáratula!$G$37)>G18,B18+2,B18+1),IF(DAY(Cáratula!$G$37)>G18,B18+1,B18)) -> 2 | F18: 0.5 | G18: 25 | H18: 17 | I18: Total Ingresos Fijos | K18: =IF(AND(Cáratula!G9="Red_Salud_APLAO",Cáratula!G13="Nombrado Asistencial Médico"),150,IF(AND(Cáratula!G9="Red_Salud_APLAO",Cáratula!G13="Nombrado Profesional de Salud"),80,IF(AND(Cáratula!G9="Red_Salud_APLAO",Cáratula!G13="Nombrado Técnico Asistencial"),50,0))) -> 0 | M18: =IF(Cáratula!$G$9<>A18,"",IF(DAY(Cáratula!$G$37)<H18,1,IF(AND(DAY(Cáratula!$G$37)>=H18,DAY(Cáratula!$G$37)<G18),0,IF(DAY(Cáratula!$G$37)>=G18,1,""))))
A19: UTES_N6 | B19: 1 | C19: 2 | D19: =IF(G19>H19,IF(DAY(Cáratula!$G$37)>G19,B19+1,B19+0),IF(DAY(Cáratula!$G$37)>G19,B19+1,B19)) -> 1 | E19: =IF(G19>H19,IF(DAY(Cáratula!$G$37)>G19,B19+2,B19+1),IF(DAY(Cáratula!$G$37)>G19,B19+1,B19)) -> 2 | F19: 0.5 | G19: 28 | H19: 15 | I19: Total Ingresos Fijos | M19: =IF(Cáratula!$G$9<>A19,"",IF(DAY(Cáratula!$G$37)<H19,1,IF(AND(DAY(Cáratula!$G$37)>=H19,DAY(Cáratula!$G$37)<G19),0,IF(DAY(Cáratula!$G$37)>=G19,1,""))))
A20: Gobierno_Regional_Loreto | B20: 1 | C20: 2 | D20: 1 | E20: 2 | F20: 0.5 | G20: 30 | H20: 15 | I20: Total Ingresos Fijos | M20: =IF(AND(Cáratula!$G$9=A20,DAY(Cáratula!$G$37)<H20),1,IF(AND(Cáratula!$G$9=A20,DAY(Cáratula!$G$37))>=H20,0,0)) -> 0

Sheet Cargos
A1: Ejército_del_Perú | B1: Remuneración Consolidada | C1: Bonificación FFAA | E1: Policia_Nacional_del_Perú | F1: Remuneración Consolidada | G1: Bonificación trabajo efectivo | H1: Bonificación Alto riesgo a la vida | J1: Marina_de_Guerra | K1: Remuneración Consolidada | L1: Bonificación FFAA | N1: RENIEC | P1: DIRIS_Lima_Norte | R1: Hospital_de_apoyo_Iquitos | T1: ESSALUD | V1: SENASA | X1: ONPE | Z1: U_San_Juan_Bautista | AB1: DIRIS_Lima_Centro | AD1: Ministerio_Defensa | AF1: UE403_Morropon | AH1: Fuerza_Aerea_del_Perú | AJ1: EPSEL | AL1: UNAP | AN1: Hospital_Regional_Loreto | AP1: Red_Salud_APLAO | AR1: UTES_N6 | AT1: Gobierno_Regional_Loreto
A2: General de División | B2: 10630.52 | C2: 2750 | E2: Teniente General | F2: 10630.52 | G2: 2750 | H2: 3250 | J2: Vicealmirante | K2: 10630.52 | L2: 2750 | N2: CAS Indeterminado | P2: NPS Asistencial | R2: NPS Asistencial | T2: Asistencial | V2: Nombrado | X2: CAP Nombrado | Z2: Indeterminado | AB2: NPS Asistencial | AD2: Nombrado | AF2: Nombrado | AH2: Teniente General | AJ2: Ind_Administrativo | AL2: Nombrado | AN2: Nombrado Asistencial | AP2: Nombrado Asistencial Médico | AR2: Nombrado Asistencial | AT2: Nombrados
A3: General de Brigada | B3: 10370.07 | C3: 2550 | E3: General | F3: 10370.07 | G3: 2550 | H3: 2700 | J3: Contralmirante | K3: 10370.07 | L3: 2550 | N3: DS. Nro 001-98-TR | P3: PS Asistencial | R3: PS Asistencial | T3: Administrativo | V3: CAS Indeterminado | X3: CAP Indeterminado | AB3: PS Asistencial | AD3: CAS Indeterminado | AF3: CAS Indeterminado | AH3: Mayor General | AJ3: Ind_Obrero | AL3: Indeterminado | AN3: Nombrado Administrativo | AP3: Nombrado Profesional de Salud | AR3: Nombrado Administrativo | AT3: CAS Indeterminado
A4: Coronel | B4: 8568.2 | C4: 2200 | E4: Coronel | F4: 8568.2 | G4: 2200 | H4: 2150 | J4: Capitán de Navío | K4: 8568.2 | L4: 2200 | P4: NPS Administrativo | R4: NPS Administrativo | V4: CAS Regular | X4: CAS Indeterminado | AB4: NPS Administrativo | AH4: Coronel | AJ4: Ind_Funcionario | AL4: CAS Indeterminado | AN4: CAS Indeterminado | AP4: Nombrado Técnico Asistencial | AR4: CAS Indeterminado
A5: Teniente Coronel | B5: 5305.69 | C5: 2200 | E5: Comandante | F5: 5305.69 | G5: 2200 | H5: 2000 | J5: Capitán de Fragata | K5: 5305.69 | L5: 2200 | P5: PS Administrativo | R5: PS Administrativo | AB5: PS Administrativo | AH5: Comandante | AP5: Administrativos
A6: Mayor | B6: 4035.35 | C6: 1800 | E6: Mayor | F6: 4035.35 | G6: 1800 | H6: 1750 | J6: Capitán de Corbeta | K6: 4035.35 | L6: 1800 | P6: CAS Indeterminado | R6: NPS CAS Asistencial | AB6: CAS Indeterminado | AH6: Mayor General
A7: Capitán | B7: 3353.93 | C7: 1650 | E7: Capitán | F7: 3353.93 | G7: 1650 | H7: 1750 | J7: Teniente Primero | K7: 3353.93 | L7: 1650 | R7: PS CAS Asistencial | AH7: Capitan
A8: Teniente | B8: 2800.08 | C8: 1650 | E8: Teniente | F8: 2800.08 | G8: 1650 | H8: 1650 | J8: Teniente Segundo | K8: 2800.08 | L8: 1650 | R8: NPS CAS Administrativo | AH8: Teniente
A9: Sub Teniente | B9: 2734.17 | C9: 1450 | E9: Alferez | F9: 2734.17 | G9: 1450 | H9: 1500 | J9: Alferez de Fragata | K9: 2734.17 | L9: 1450 | R9: PS CAS Administrativo | AH9: Alferez
A10: Técnico Jefe Superior | B10: 3309.28 | C10: 1650 | E10: Sub Oficial Superior | F10: 3309.28 | G10: 1650 | H10: 1750 | J10: Técnico Superior Primero | K10: 3309.28 | L10: 1650 | AH10: Técnico Supervisor
A11: Técnico Jefe | B11: 3175.59 | C11: 1650 | E11: Sub Oficial Brigadier | F11: 3175.59 | G11: 1650 | H11: 1650 | J11: Técnico Superior Segundo | K11: 3175.59 | L11: 1650 | AH11: Técnico Inspector
A12: Técnico de Primera | B12: 2953.53 | C12: 1450 | E12: Sub Oficial Técnico de Primera | F12: 2953.53 | G12: 1450 | H12: 1500 | J12: Técnico Primero | K12: 2953.53 | L12: 1450 | AH12: Técnico de Primera
A13: Técnico de Segunda | B13: 2763.25 | C13: 1300 | E13: Sub Oficial Técnico de Segunda | F13: 2763.25 | G13: 1300 | H13: 1200 | J13: Técnico Segundo | K13: 2763.25 | L13: 1300 | AH13: Técnico de Segunda
A14: Técnico de Tercera | B14: 2609.7 | C14: 1300 | E14: Sub Oficial Técnico de Tercera | F14: 2609.7 | G14: 1300 | H14: 1200 | J14: Técnico Tercero | K14: 2609.7 | L14: 1300 | AH14: Técnico de Tercera
A15: Suboficial Primera | B15: 2533.58 | C15: 1300 | E15: Sub Oficial de Primera | F15: 2533.58 | G15: 1300 | H15: 1200 | J15: Oficial de Mar Primero | K15: 2533.58 | L15: 1300 | AH15: Suboficial de Primera
A16: Suboficial Segunda | B16: 2486.59 | C16: 1300 | E16: Sub Oficial de Segunda | F16: 2486.59 | G16: 1300 | H16: 1200 | J16: Oficial de Mar Segundo | K16: 2486.59 | L16: 1300 | AH16: Suboficial de Segunda
A17: Suboficial Tercera | E17: Sub Oficial de Tercera | AH17: Suboficial de Tercera
A18: Personal Administrativo | E18: Personal Administrativo | AH18: Personal Administrativo

Sheet Cáratula
B7: Calculadora Convenios Públicos
B9: Convenio | G9: Policia_Nacional_del_Perú
B11: RCI | G11: =L14 -> 0.45 | J11: =IF(OR(AND(G9="DIRIS_Lima_Norte",G13="CAS Indeterminado"),AND(G9="DIRIS_Lima_Centro",G13="CAS Indeterminado")),0.4,VLOOKUP(G9,Base!$A:$F,6,0)) -> 0.45 | K11: =IF(AND(G9="RENIEC",G13="CAS Indeterminado"),0.45,J11) -> 0.45 | L11: =IF(AND(G9="Policia_Nacional_del_Perú",G13="Sub Oficial de Tercera"),0.4,K11) -> 0.45
B13: Cargo Laboral | G13: Sub Oficial de Segunda | J13: =IF(AND(G9="UE403_Morropon",G13="CAS Indeterminado"),0.42,K13) -> 0.45 | K13: =IF(AND(G9="UE403_Morropon",G13="Nombrado"),0.49,L13) -> 0.45 | L13: =IF(AND(G9="Policia_Nacional_del_Perú",G13="Sub Oficial de Tercera menor a 55 años"),0.3,L11) -> 0.45
B14: Ingresos | L14: =IF(AND(G9="Ejército_del_Perú",G13="Suboficial Tercera"),0.45,J13) -> 0.45
B15: Total de Ingresos | G15: 3927.23
B16: Ingreso variable mansual
B17: Promedio de Ingresos variables (3 últimos meses)
B18: Sumatoria de otros ingresos fijos (CAFAE)
B20: Ingresos no constantes
B21: Sumatoria de ingresos no constantes
B23: Descuentos de Ley
B24: Sumatoria de los descuentos de Ley | G24: 183.88
B26: Disponible para endeudamiento | G26: =IF(G9="U_San_Juan_Bautista",G15*J11,((G15-G16+(G17*0.5)+G18-G21-G24)*L13)) -> 1684.5075
B28: Reserva | G28: =VLOOKUP(G9,Base!$A:$K,11,0) -> 0
B29: Sumatoria de facultativos | G29: 39
B31: Primer cálculo de Ingreso Neto Disponible | G31: =IF(G15=0,"",K31) -> 1645.5075 | K31: =IF(G9="Ejercito_del_Perú",G26-G28-G29-5,G26-G28-G29) -> 1645.5075
B34: Ingrese Monto a Solicitar | G34: 83500
B35: Número de cuotas (En meses) | G35: 72
B36: Moneda | G36: Soles
B37: Fecha de desembolso | G37: 46129
B38: Fecha de primer vencimiento | G38: =DATE(YEAR(EDATE(G37,D70)),MONTH(EDATE(G37,D70)),D69) -> 46218
B39: Ingrese Tasa de Interés Efectiva Anual | G39: 0.1099 | J39: TNA 365 | K39: =(((1+G39)^(1/12)-1)*12)*365/360 -> 0.10617875 | O39: Tasa de desgravamen anual | P39: =G43*12 -> 0.009204
B40: Envío de estado de cuenta | G40: Virtual | J40: i | K40: =K39/365 -> 0.00029090068 | O40: d | P40: =P39/365 -> 2.5216438e-05
B41: Tipo de Seguro de Desgravamen | G41: Individual | J41: Factor por tiempo | K41: =K40*31 -> 0.0090179211 | O41: Factor por tiempo | P41: =P40*31 -> 0.00078170959
G42: Sin retorno
B43: Tasa mensual de Seguro de Desgravamen | G43: =VLOOKUP(G42,J46:$K$51,2,0) -> 0.000767
B44: PG (Solo equipo SCC) | G44: =VLOOKUP(G9,Base!$A$1:$M$20,13,0) -> 1
B46: Resumen de Carga Crediticia | J46: Endosado | K46: 0
P48: LNU | Q48: Hipotecario | R48: CEF | S48: Vehicular | T48: Tarjeta
D50: Deuda cuota BCP | E50: Deuda cuota no BCP | F50: Saldo | G50: Saldo Actualizado | H50: Cuota Actualizada | J50: Sin retorno | K50: 0.000767 | O50: A | P50: 0.003306 | Q50: 0.01 | R50: 0.035 | S50: 0.022 | T50: 0.078
B51: Crédito Hipotecario | H51: =IF(AND(E51<>"",F51<>"",G51<>""),L51,N51) -> 0 | J51: Con retorno | K51: 0.000997 | L51: =G51/F51*E51 -> #DIV/0! | N51: =IF(E51="",G51*(Q54),E51) -> 0 | O51: B | P51: 0.005306 | Q51: 0.01 | R51: 0.037 | S51: 0.023 | T51: 0.082 | X51: CEF
B52: Crédito Efectivo | H52: =IF(AND(E52<>"",F52<>"",G52<>""),L52,N52) -> 0 | L52: =G52/F52*E52 -> #DIV/0! | N52: =IF(E52="",G53*(R54),E52) -> 0 | O52: C | P52: 0.006583 | Q52: 0.011 | R52: 0.039 | S52: 0.023 | T52: 0.084 | W52: A | X52: 0.035
B53: Crédito Vehicular | H53: =IF(AND(E53<>"",F53<>"",G53<>""),L53,N53) -> 0 | K53: =IF(K57<=J60,"Continuar","Sobre endeudado") -> Continuar | L53: =G53/F53*E53 -> #DIV/0! | N53: =IF(E53="",G54*(S54),E53) -> 0 | O53: D | P53: 0.007139 | Q53: 0.011 | R53: 0.041 | S53: 0.023 | T53: 0.087 | W53: B | X53: 0.037
B54: Pyme | H54: =IF(AND(E54<>"",F54<>"",G54<>""),L54,N54) -> 0 | L54: =G54/F54*E54 -> #DIV/0! | N54: =IF(E54="",G54*(T54),E54) -> 0 | O54: E | P54: 0.007417 | Q54: 0.011 | R54: 0.044 | S54: 0.024 | T54: 0.088 | W54: C | X54: 0.039
B55: Comercial | H55: =IF(AND(E55<>"",F55<>"",G55<>""),L55,N55) -> 0 | L55: =G55/F55*E55 -> #DIV/0! | N55: =IF(E55="",G55*0.028,E55) -> 0 | O55: SS | P55: 0.007417 | Q55: 0.011 | R55: 0.044 | S55: 0.024 | T55: 0.088 | W55: D | X55: 0.041
B56: Deuda Indirecta | H56: =IF(AND(E56<>"",F56<>"",G56<>""),L56,N56) -> 0 | L56: =G56/F56*E56 -> #DIV/0! | N56: =IF(E56="",G56*0.000694,E56) -> 0 | W56: E | X56: 0.044
B57: Línea utilizada de tarjeta de Crédito | E57: 5 | F57: 65 | H57: =IF(AND(E57<>"",F57<>"",G57<>""),L57,N57) -> 5 | K57: =((G51/100)+(G53*0.035)+(G54*0.022)+(G56*0.0006944)+(G57*0.078)+(G58*0.003306)+E51+E52+E53+E56+E57+E58+D51+D52+D53+D54+D55+E55+D56+E54+D57+D58)/(G15-G21+G18-G24-G29) -> 0.0097183042 | L57: =G57/F57*E57 -> 0 | N57: =IF(E57="",G57*(P54),E57) -> 5 | W57: SS | X57: 0.044
B58: Línea no utilizada | E58: 31 | F58: 8435 | H58: =IF(AND(E58<>"",F58<>"",G58<>""),L58,N58) -> 31 | J58: =P54 -> 0.007417 | L58: =G58/F58*E58 -> 0 | N58: =IF(E58="",G58*J58,E58) -> 31
B59: % Endeudamiento | G59: =IF(K57=0,"",K57) -> 0.0097183042
...

Sheet Cronograma
C7: Cronograma
B8: Nota: Todo crédito se encuentra sujeto a la evaluación crediticia del Banco, quien determina el monto y plazo a otorgar. Este documento ha sido emitido en base a la información proporcionada por el cliente y tiene carácter referencial | P8: 45762
P9: 45792
C10: Tasa de interés Efectiva Anual (En base a 360 días) | K10: =Cáratula!G39 -> 0.1099
C11: Tasa de Costo Efectiva Anual (En base a 360 días) | K11: =IF(Cáratula!K69="","",Cáratula!K69) -> 0.12987668
C13: Cantidad total a pagar
I16: Interés | J16: Seguro desgravamen | K16: Amortización | L16: Cuota | M16: Envío físico de estado de cuenta | N16: Evaluación de póliza endosada | O16: Seguro de protección financiera | P16: Cuota
B17: Totales a pagar | I17: =SUM(I20:I1048576) -> 32600.651 | J17: =SUM(J20:J1048576) -> 2766.9993 | K17: =SUM(K20:K1048576) -> 83763.028 | L17: =SUM(L20:L1048576) -> 118391.6 | M17: =SUM(M20:M1048576) -> 0 | N17: =SUM(N20:N1048576) -> 0 | O17: =SUM(O20:O1048576) -> 0 | P17: =SUM(P21:P1048576) -> 118391.6
B19: N° | C19: Fecha | D19: T. Días | E19: T. Días cuota | F19: Saldo anterior | G19: Capital | H19: Factor Interés | I19: Interés | J19: Seguro desgravamen | K19: Amortización | L19: Cuota | M19: Envío físico de estado de cuenta | N19: Evaluación de póliza endosada | O19: Seguro de protección financiera | P19: Cuota
C20: =IF(DAY(Cáratula!G37)>=Cáratula!D69,"",(IF(Cáratula!D68=2,(EDATE(C21,-1)),""))) | D20: =IF(C20="","",(C20-Cáratula!G37)) | F20: =IF(C20="","",(IF(Cáratula!D68=2,Cáratula!G34,""))) | G20: =IF(F20="","",F20) | H20: =IF(G20="","",(Cáratula!K39/365*D20)) | I20: =IF(H20="","",(H20*F20)) | J20: =IF(C20="","",G20*Cáratula!P40*D20) | P20: =-Cáratula!G34 -> -83500
C21: =EDATE(C22,-1) -> 46157 | D21: =C21-Cáratula!G37 -> 28 | E21: =IF(C20="",(C21-Cáratula!G37),(C21-C20)) -> 28 | F21: =IF(F20="",Cáratula!G34,G20) -> 83500 | G21: =IF(C20="",F21,G20) -> 83500 | H21: =Cáratula!$K$39/365*E21 -> 0.0081452191 | I21: =H21*F21 -> 680.12579 | J21: =IF(C20="",F21*E21*Cáratula!$P$40,Cáratula!P40*E21*G20) -> 58.956033
C22: =EDATE(C23,-1) -> 46188 | D22: =C22-Cáratula!G37 -> 59 | E22: =C22-C21 -> 31 | F22: =IF(C20="",G21,G22) -> 83500 | G22: =IF(C20="",G21+I22+J22,G21+I21+J21) -> 84318.269 | H22: =IF(OR($B23=""),$B23,(Cáratula!$K$39/365*E22)) -> 0.0090179211 | I22: =IF(OR($B23=""),$B23,(H22*F22)) -> 752.99641 | J22: =IF(C20="",Cáratula!$P$40*E22*G21,Cáratula!P40*E22*G22) -> 65.272751 | K22: =IF(OR($B23=""),$B23,(L22-I22-J22)) -> -818.26916 | P22: -
B23: 1 | C23: =Cáratula!G38 -> 46218 | D23: =IF(OR($B24=""),"",$C23-Cáratula!$G$38) -> 0 | E23: =IF(OR($B24=""),"",C23-C22) -> 30 | F23: =G22 -> 84318.269 | G23: =IF(C20="",G22,G22+I22+J22) -> 84318.269 | H23: =IF(OR($B24=""),$B24,(Cáratula!$K$39/365*E23)) -> 0.0087270204 | I23: =IF(C20="",((H23*F23)+I21),((H23*F23)+I20)) -> 1415.973 | J23: =IF(OR($B24=""),"",IF(C21="",Cáratula!$P$40*E23*G22,Cáratula!P40*E23*G23)) -> 63.786193 | K23: =L23-I23-J23 -> 164.5685 | L23: =Cáratula!K65+$W$24 -> 1644.3277 | M23: =IF(OR($B24=""),"",IF(Cáratula!$G$40="Físico",10,0)) -> 0 | P23: =IF(OR($B24=""),"",O23+N23+M23+L23) -> 1644.3277
B24: =IF($B23=Cáratula!$G$35,$B$21,IF(OR($B23="",$B23=$B$21),"",$B23+1)) -> 2 | C24: =IF(OR($B25=""),$B25,IF(DAY(EOMONTH($C23,1))<Cáratula!$D$69,EOMONTH($C23,1),DATE(YEAR(EOMONTH($C23,1)),MONTH(EOMONTH($C23,1)),Cáratula!$D$69))) -> 46249 | D24: =IF(OR($B25=""),"",$C24-Cáratula!$G$38) -> 31 | E24: =IF(OR($B25=""),"",C24-C23) -> 31 | F24: =IF(OR($B25=""),"",G23) -> 84318.269 | G24: =IF(OR($B25=""),"",F24-K23) -> 84153.701 | H24: =IF(OR($B25=""),$B25,(Cáratula!$K$39/365*E24)) -> 0.0090179211 | I24: =IF(OR($B25=""),$B25,(H24*G24)) -> 758.89143 | J24: =IF(OR($B25=""),"",IF(C22="",Cáratula!$P$40*E24*G23,Cáratula!$P$40*E24*G24)) -> 65.783755 | K24: =IF(OR($B25=""),"",L24-I24-J24) -> 819.65255 | L24: =IF(OR($B25=""),"",L23) -> 1644.3277 | M24: =M23 -> 0 | P24: =O24+N24+M24+L24 -> 1644.3277 | W24: 4
B25: =IF($B24=Cáratula!$G$35,$B$21,IF(OR($B24="",$B24=$B$21),"",$B24+1)) -> 3 | C25: =IF(OR($B26=""),$B26,IF(DAY(EOMONTH($C24,1))<Cáratula!$D$69,EOMONTH($C24,1),DATE(YEAR(EOMONTH($C24,1)),MONTH(EOMONTH($C24,1)),Cáratula!$D$69))) -> 46280 | D25: =IF(OR($B26=""),"",$C25-Cáratula!$G$38) -> 62 | E25: =IF(OR($B26=""),"",C25-C24) -> 31 | F25: =IF(OR($B26=""),"",G24) -> 84153.701 | G25: =IF(OR($B26=""),"",F25-K24) -> 83334.048 | H25: =IF(OR($B26=""),$B26,(Cáratula!$K$39/365*E25)) -> 0.0090179211 | I25: =IF(OR($B26=""),$B26,(H25*G25)) -> 751.49987 | J25: =IF(OR($B26=""),"",IF(C23="",Cáratula!$P$40*E25*G24,Cáratula!$P$40*E25*G25)) -> 65.143025 | K25: =IF(OR($B26=""),"",L25-I25-J25) -> 827.68484 | L25: =IF(OR($B26=""),"",L24) -> 1644.3277 | M25: =IF(OR($B26=""),"",IF(Cáratula!$G$40="Físico",10,0)) -> 0 | P25: =IF(OR($B26=""),"",O25+N25+M25+L25) -> 1644.3277
B26: =IF($B25=Cáratula!$G$35,$B$21,IF(OR($B25="",$B25=$B$21),"",$B25+1)) -> 4 | C26: =IF(OR($B27=""),$B27,IF(DAY(EOMONTH($C25,1))<Cáratula!$D$69,EOMONTH($C25,1),DATE(YEAR(EOMONTH($C25,1)),MONTH(EOMONTH($C25,1)),Cáratula!$D$69))) -> 46310 | D26: =IF(OR($B27=""),"",$C26-Cáratula!$G$38) -> 92 | E26: =IF(OR($B27=""),"",C26-C25) -> 30 | F26: =IF(OR($B27=""),"",G25) -> 83334.048 | G26: =IF(OR($B27=""),"",F26-K25) -> 82506.363 | H26: =IF(OR($B27=""),$B27,(Cáratula!$K$39/365*E26)) -> 0.0087270204 | I26: =IF(OR($B27=""),$B27,(H26*G26)) -> 720.03472 | J26: =IF(OR($B27=""),"",IF(C24="",Cáratula!$P$40*E26*G25,Cáratula!$P$40*E26*G26)) -> 62.415499 | K26: =IF(OR($B27=""),"",L26-I26-J26) -> 861.87752 | L26: =IF(OR($B27=""),"",L25) -> 1644.3277 | M26: =IF(OR($B27=""),"",IF(Cáratula!$G$40="Físico",10,0)) -> 0 | P26: =IF(OR($B27=""),"",O26+N26+M26+L26) -> 1644.3277
B27: =IF($B26=Cáratula!$G$35,$B$21,IF(OR($B26="",$B26=$B$21),"",$B26+1)) -> 5 | C27: =IF(OR($B28=""),$B28,IF(DAY(EOMONTH($C26,1))<Cáratula!$D$69,EOMONTH($C26,1),DATE(YEAR(EOMONTH($C26,1)),MONTH(EOMONTH($C26,1)),Cáratula!$D$69))) -> 46341 | D27: =IF(OR($B28=""),"",$C27-Cáratula!$G$38) -> 123 | E27: =IF(OR($B28=""),"",C27-C26) -> 31 | F27: =IF(OR($B28=""),"",G26) -> 82506.363 | G27: =IF(OR($B28=""),"",F27-K26) -> 81644.486 | H27: =IF(OR($B28=""),$B28,(Cáratula!$K$39/365*E27)) -> 0.0090179211 | I27: =IF(OR($B28=""),$B28,(H27*G27)) -> 736.26353 | J27: =IF(OR($B28=""),"",IF(C25="",Cáratula!$P$40*E27*G26,Cáratula!$P$40*E27*G27)) -> 63.822277 | K27: =IF(OR($B28=""),"",L27-I27-J27) -> 844.24193 | L27: =IF(OR($B28=""),"",L26) -> 1644.3277 | M27: =IF(OR($B28=""),"",IF(Cáratula!$G$40="Físico",10,0)) -> 0 | P27: =IF(OR($B28=""),"",O27+N27+M27+L27) -> 1644.3277
B28: =IF($B27=Cáratula!$G$35,$B$21,IF(OR($B27="",$B27=$B$21),"",$B27+1)) -> 6 | C28: =IF(OR($B29=""),$B29,IF(DAY(EOMONTH($C27,1))<Cáratula!$D$69,EOMONTH($C27,1),DATE(YEAR(EOMONTH($C27,1)),MONTH(EOMONTH($C27,1)),Cáratula!$D$69))) -> 46371 | D28: =IF(OR($B29=""),"",$C28-Cáratula!$G$38) -> 153 | E28: =IF(OR($B29=""),"",C28-C27) -> 30 | F28: =IF(OR($B29=""),"",G27) -> 81644.486 | G28: =IF(OR($B29=""),"",F28-K27) -> 80800.244 | H28: =IF(OR($B29=""),$B29,(Cáratula!$K$39/365*E28)) -> 0.0087270204 | I28: =IF(OR($B29=""),$B29,(H28*G28)) -> 705.14538 | J28: =IF(OR($B29=""),"",IF(C26="",Cáratula!$P$40*E28*G27,Cáratula!$P$40*E28*G28)) -> 61.124831 | K28: =IF(OR($B29=""),"",L28-I28-J28) -> 878.05753 | L28: =IF(OR($B29=""),"",L27) -> 1644.3277 | M28: =IF(OR($B29=""),"",IF(Cáratula!$G$40="Físico",10,0)) -> 0 | P28: =IF(OR($B29=""),"",O28+N28+M28+L28) -> 1644.3277
B29: =IF($B28=Cáratula!$G$35,$B$21,IF(OR($B28="",$B28=$B$21),"",$B28+1)) -> 7 | C29: =IF(OR($B30=""),$B30,IF(DAY(EOMONTH($C28,1))<Cáratula!$D$69,EOMONTH($C28,1),DATE(YEAR(EOMONTH($C28,1)),MONTH(EOMONTH($C28,1)),Cáratula!$D$69))) -> 46402 | D29: =IF(OR($B30=""),"",$C29-Cáratula!$G$38) -> 184 | E29: =IF(OR($B30=""),"",C29-C28) -> 31 | F29: =IF(OR($B30=""),"",G28) -> 80800.244 | G29: =IF(OR($B30=""),"",F29-K28) -> 79922.186 | H29: =IF(OR($B30=""),$B30,(Cáratula!$K$39/365*E29)) -> 0.0090179211 | I29: =IF(OR($B30=""),$B30,(H29*G29)) -> 720.73197 | J29: =IF(OR($B30=""),"",IF(C27="",Cáratula!$P$40*E29*G28,Cáratula!$P$40*E29*G29)) -> 62.475939 | K29: =IF(OR($B30=""),"",L29-I29-J29) -> 861.11983 | L29: =IF(OR($B30=""),"",L28) -> 1644.3277 | M29: =IF(OR($B30=""),"",IF(Cáratula!$G$40="Físico",10,0)) -> 0 | P29: =IF(OR($B30=""),"",O29+N29+M29+L29) -> 1644.3277
B30: =IF($B29=Cáratula!$G$35,$B$21,IF(OR($B29="",$B29=$B$21),"",$B29+1)) -> 8 | C30: =IF(OR($B31=""),$B31,IF(DAY(EOMONTH($C29,1))<Cáratula!$D$69,EOMONTH($C29,1),DATE(YEAR(EOMONTH($C29,1)),MONTH(EOMONTH($C29,1)),Cáratula!$D$69))) -> 46433 | D30: =IF(OR($B31=""),"",$C30-Cáratula!$G$38) -> 215 | E30: =IF(OR($B31=""),"",C30-C29) -> 31 | F30: =IF(OR($B31=""),"",G29) -> 79922.186 | G30: =IF(OR($B31=""),"",F30-K29) -> 79061.066 | H30: =IF(OR($B31=""),$B31,(Cáratula!$K$39/365*E30)) -> 0.0090179211 | I30: =IF(OR($B31=""),$B31,(H30*G30)) -> 712.96646 | J30: =IF(OR($B31=""),"",IF(C28="",Cáratula!$P$40*E30*G29,Cáratula!$P$40*E30*G30)) -> 61.802794 | K30: =IF(OR($B31=""),"",L30-I30-J30) -> 869.55849 | L30: =IF(OR($B31=""),"",L29) -> 1644.3277 | M30: =IF(OR($B31=""),"",IF(Cáratula!$G$40="Físico",10,0)) -> 0 | P30: =IF(OR($B31=""),"",O30+N30+M30+L30) -> 1644.3277
B31: =IF($B30=Cáratula!$G$35,$B$21,IF(OR($B30="",$B30=$B$21),"",$B30+1)) -> 9 | C31: =IF(OR($B32=""),$B32,IF(DAY(EOMONTH($C30,1))<Cáratula!$D$69,EOMONTH($C30,1),DATE(YEAR(EOMONTH($C30,1)),MONTH(EOMONTH($C30,1)),Cáratula!$D$69))) -> 46461 | D31: =IF(OR($B32=""),"",$C31-Cáratula!$G$38) -> 243 | E31: =IF(OR($B32=""),"",C31-C30) -> 28 | F31: =IF(OR($B32=""),"",G30) -> 79061.066 | G31: =IF(OR($B32=""),"",F31-K30) -> 78191.508 | H31: =IF(OR($B32=""),$B32,(Cáratula!$K$39/365*E31)) -> 0.0081452191 | I31: =IF(OR($B32=""),$B32,(H31*G31)) -> 636.88696 | J31: =IF(OR($B32=""),"",IF(C29="",Cáratula!$P$40*E31*G30,Cáratula!$P$40*E31*G31)) -> 55.207918 | K31: =IF(OR($B32=""),"",L31-I31-J31) -> 952.23286 | L31: =IF(OR($B32=""),"",L30) -> 1644.3277 | M31: =IF(OR($B32=""),"",IF(Cáratula!$G$40="Físico",10,0)) -> 0 | P31: =IF(OR($B32=""),"",O31+N31+M31+L31) -> 1644.3277
B32: =IF($B31=Cáratula!$G$35,$B$21,IF(OR($B31="",$B31=$B$21),"",$B31+1)) -> 10 | C32: =IF(OR($B33=""),$B33,IF(DAY(EOMONTH($C31,1))<Cáratula!$D$69,EOMONTH($C31,1),DATE(YEAR(EOMONTH($C31,1)),MONTH(EOMONTH($C31,1)),Cáratula!$D$69))) -> 46492 | D32: =IF(OR($B33=""),"",$C32-Cáratula!$G$38) -> 274 | E32: =IF(OR($B33=""),"",C32-C31) -> 31 | F32: =IF(OR($B33=""),"",G31) -> 78191.508 | G32: =IF(OR($B33=""),"",F32-K31) -> 77239.275 | H32: =IF(OR($B33=""),$B33,(Cáratula!$K$39/365*E32)) -> 0.0090179211 | I32: =IF(OR($B33=""),$B33,(H32*G32)) -> 696.53769 | J32: =IF(OR($B33=""),"",IF(C30="",Cáratula!$P$40*E32*G31,Cáratula!$P$40*E32*G32)) -> 60.378682 | K32: =IF(OR($B33=""),"",L32-I32-J32) -> 887.41137 | L32: =IF(OR($B33=""),"",L31) -> 1644.3277 | M32: =IF(OR($B33=""),"",IF(Cáratula!$G$40="Físico",10,0)) -> 0 | P32: =IF(OR($B33=""),"",O32+N32+M32+L32) -> 1644.3277
B33: =IF($B32=Cáratula!$G$35,$B$21,IF(OR($B32="",$B32=$B$21),"",$B32+1)) -> 11 | C33: =IF(OR($B34=""),$B34,IF(DAY(EOMONTH($C32,1))<Cáratula!$D$69,EOMONTH($C32,1),DATE(YEAR(EOMONTH($C32,1)),MONTH(EOMONTH($C32,1)),Cáratula!$D$69))) -> 46522 | D33: =IF(OR($B34=""),"",$C33-Cáratula!$G$38) -> 304 | E33: =IF(OR($B34=""),"",C33-C32) -> 30 | F33: =IF(OR($B34=""),"",G32) -> 77239.275 | G33: =IF(OR($B34=""),"",F33-K32) -> 76351.864 | H33: =IF(OR($B34=""),$B34,(Cáratula!$K$39/365*E33)) -> 0.0087270204 | I33: =IF(OR($B34=""),$B34,(H33*G33)) -> 666.32427 | J33: =IF(OR($B34=""),"",IF(C31="",Cáratula!$P$40*E33*G32,Cáratula!$P$40*E33*G33)) -> 57.759662 | K33: =IF(OR($B34=""),"",L33-I33-J33) -> 920.2438 | L33: =IF(OR($B34=""),"",L32) -> 1644.3277 | M33: =IF(OR($B34=""),"",IF(Cáratula!$G$40="Físico",10,0)) -> 0 | P33: =IF(OR($B34=""),"",O33+N33+M33+L33) -> 1644.3277
B34: =IF($B33=Cáratula!$G$35,$B$21,IF(OR($B33="",$B33=$B$21),"",$B33+1)) -> 12 | C34: =IF(OR($B35=""),$B35,IF(DAY(EOMONTH($C33,1))<Cáratula!$D$69,EOMONTH($C33,1),DATE(YEAR(EOMONTH($C33,1)),MONTH(EOMONTH($C33,1)),Cáratula!$D$69))) -> 46553 | D34: =IF(OR($B35=""),"",$C34-Cáratula!$G$38) -> 335 | E34: =IF(OR($B35=""),"",C34-C33) -> 31 | F34: =IF(OR($B35=""),"",G33) -> 76351.864 | G34: =IF(OR($B35=""),"",F34-K33) -> 75431.62 | H34: =IF(OR($B35=""),$B35,(Cáratula!$K$39/365*E34)) -> 0.0090179211 | I34: =IF(OR($B35=""),$B35,(H34*G34)) -> 680.2364 | J34: =IF(OR($B35=""),"",IF(C32="",Cáratula!$P$40*E34*G33,Cáratula!$P$40*E34*G34)) -> 58.965621 | K34: =IF(OR($B35=""),"",L34-I34-J34) -> 905.12572 | L34: =IF(OR($B35=""),"",L33) -> 1644.3277 | M34: =IF(OR($B35=""),"",IF(Cáratula!$G$40="Físico",10,0)) -> 0 | P34: =IF(OR($B35=""),"",O34+N34+M34+L34) -> 1644.3277
B35: =IF($B34=Cáratula!$G$35,$B$21,IF(OR($B34="",$B34=$B$21),"",$B34+1)) -> 13 | C35: =IF(OR($B36=""),$B36,IF(DAY(EOMONTH($C34,1))<Cáratula!$D$69,EOMONTH($C34,1),DATE(YEAR(EOMONTH($C34,1)),MONTH(EOMONTH($C34,1)),Cáratula!$D$69))) -> 46583 | D35: =IF(OR($B36=""),"",$C35-Cáratula!$G$38) -> 365 | E35: =IF(OR($B36=""),"",C35-C34) -> 30 | F35: =IF(OR($B36=""),"",G34) -> 75431.62 | G35: =IF(OR($B36=""),"",F35-K34) -> 74526.494 | H35: =IF(OR($B36=""),$B36,(Cáratula!$K$39/365*E35)) -> 0.0087270204 | I35: =IF(OR($B36=""),$B36,(H35*G35)) -> 650.39424 | J35: =IF(OR($B36=""),"",IF(C33="",Cáratula!$P$40*E35*G34,Cáratula!$P$40*E35*G35)) -> 56.378782 | K35: =IF(OR($B36=""),"",L35-I35-J35) -> 937.55472 | L35: =IF(OR($B36=""),"",L34) -> 1644.3277 | M35: =IF(OR($B36=""),"",IF(Cáratula!$G$40="Físico",10,0)) -> 0 | P35: =IF(OR($B36=""),"",O35+N35+M35+L35) -> 1644.3277
B36: =IF($B35=Cáratula!$G$35,$B$21,IF(OR($B35="",$B35=$B$21),"",$B35+1)) -> 14 | C36: =IF(OR($B37=""),$B37,IF(DAY(EOMONTH($C35,1))<Cáratula!$D$69,EOMONTH($C35,1),DATE(YEAR(EOMONTH($C35,1)),MONTH(EOMONTH($C35,1)),Cáratula!$D$69))) -> 46614 | D36: =IF(OR($B37=""),"",$C36-Cáratula!$G$38) -> 396 | E36: =IF(OR($B37=""),"",C36-C35) -> 31 | F36: =IF(OR($B37=""),"",G35) -> 74526.494 | G36: =IF(OR($B37=""),"",F36-K35) -> 73588.94 | H36: =IF(OR($B37=""),$B37,(Cáratula!$K$39/365*E36)) -> 0.0090179211 | I36: =IF(OR($B37=""),$B37,(H36*G36)) -> 663.61925 | J36: =IF(OR($B37=""),"",IF(C34="",Cáratula!$P$40*E36*G35,Cáratula!$P$40*E36*G36)) -> 57.52518 | K36: =IF(OR($B37=""),"",L36-I36-J36) -> 923.18331 | L36: =IF(OR($B37=""),"",L35) -> 1644.3277 | M36: =IF(OR($B37=""),"",IF(Cáratula!$G$40="Físico",10,0)) -> 0 | P36: =IF(OR($B37=""),"",O36+N36+M36+L36) -> 1644.3277
... B95: =IF($B94=Cáratula!$G$35,$B$21,IF(OR($B94="",$B94=$B$21),"",$B94+1)) -> 0 | C95: =IF(OR($B96=""),$B96,IF(DAY(EOMONTH($C94,1))<Cáratula!$D$69,EOMONTH($C94,1),DATE(YEAR(EOMONTH($C94,1)),MONTH(EOMONTH($C94,1)),Cáratula!$D$69))) | D95: =IF(OR($B96=""),"",$C95-Cáratula!$G$38) | E95: =IF(OR($B96=""),"",C95-C94) | F95: =IF(OR($B96=""),"",G94) | G95: =IF(OR($B96=""),"",F95-K94) | H95: =IF(OR($B96=""),$B96,(Cáratula!$K$39/365*E95)) | I95: =IF(OR($B96=""),$B96,(H95*G95)) | J95: =IF(OR($B96=""),"",IF(C93="",Cáratula!$P$40*E95*G94,Cáratula!$P$40*E95*G95)) | K95: =IF(OR($B96=""),"",L95-I95-J95) | L95: =IF(OR($B96=""),"",L94) | M95: =IF(OR($B96=""),"",IF(Cáratula!$G$40="Físico",10,0)) | P95: =IF(OR($B96=""),"",O95+N95+M95+L95)
B96: =IF($B95=Cáratula!$G$35,$B$21,IF(OR($B95="",$B95=$B$21),"",$B95+1))
